<?xml version="1.0"?>
<robot name="vxxmd" xmlns:xacro="http://ros.org/wiki/xacro">

  <xacro:property name="robot_model"
    value="vxxmd"
    scope="global"/>

  <xacro:arg name="robot_name"                default="vxxmd"/>
  <xacro:arg name="base_link_frame"           default="base_link"/>
  <xacro:arg name="use_world_frame"           default="false"/>
  <xacro:arg name="external_urdf_loc"         default=""/>
  <xacro:arg name="hardware_type"             default="actual"/>

  <xacro:property name="mesh_directory"       value="package://interbotix_xsturret_descriptions/meshes/${robot_model}_meshes"/>
  <xacro:property name="urdf_loc"             value="$(arg external_urdf_loc)"/>
  <xacro:property name="hardware_type"        value="$(arg hardware_type)"/>

  <xacro:property name="pan_limit_effort"     value="3"/>
  <xacro:property name="pan_limit_lower"      value="-3.14"/>
  <xacro:property name="pan_limit_upper"      value="3.14"/>
  <xacro:property name="pan_limit_velocity"   value="${pi}"/>

  <xacro:property name="tilt_limit_effort"    value="3"/>
  <xacro:property name="tilt_limit_lower"     value="${radians(-90)}"/>
  <xacro:property name="tilt_limit_upper"     value="${radians(90)}"/>
  <xacro:property name="tilt_limit_velocity"  value="${pi}"/>

  <material name="interbotix_black">
    <texture filename="package://interbotix_xsturret_descriptions/meshes/interbotix_black.png"/>
  </material>

  <xacro:if value="$(arg use_world_frame)">
    <link name="world"/>
    <joint name="fixed" type="fixed">
      <parent
        link="world"/>
      <child
        link="$(arg robot_name)/$(arg base_link_frame)"/>
    </joint>
  </xacro:if>

  <link name="$(arg robot_name)/$(arg base_link_frame)">
    <visual>
      <origin
        rpy="0 0 ${pi/2}"
        xyz="0 0 0"/>
      <geometry>
        <mesh
          filename="${mesh_directory}/base.stl"
          scale="0.001 0.001 0.001"/>
      </geometry>
      <material name="interbotix_black"/>
    </visual>
    <collision>
      <origin
        rpy="0 0 ${pi/2}"
        xyz="0 0 0"/>
      <geometry>
        <mesh
          filename="${mesh_directory}/base.stl"
          scale="0.001 0.001 0.001"/>
      </geometry>
    </collision>
    <inertial>
      <origin
        rpy="0 0 0"
        xyz="-0.055803 -0.000123 0.020834"/>
      <mass value="0.997175"/>
      <inertia
        ixx="0.0022010000"
        iyy="0.0098000000"
        izz="0.0105600000"
        ixy="-0.0000197300"
        ixz="0.0012700000"
        iyz="0.0000030687"/>
    </inertial>
  </link>

  <joint name="pan" type="revolute">
    <axis xyz="0 0 1"/>
    <limit
      effort="${pan_limit_effort}"
      lower="${pan_limit_lower}"
      upper="${pan_limit_upper}"
      velocity="${pan_limit_velocity}"/>
    <origin
      rpy="0 0 0"
      xyz="0 0 0.079"/>
    <parent
      link="$(arg robot_name)/$(arg base_link_frame)"/>
    <child
      link="$(arg robot_name)/pan_link"/>
  </joint>

  <link name="$(arg robot_name)/pan_link">
    <visual>
      <origin
        rpy="0 0 ${pi/2}"
        xyz="0 0 -0.003175"/>
      <geometry>
        <mesh
          filename="${mesh_directory}/pan.stl"
          scale="0.001 0.001 0.001"/>
      </geometry>
      <material name="interbotix_black"/>
    </visual>
    <collision>
      <origin
        rpy="0 0 ${pi/2}"
        xyz="0 0 -0.003175"/>
      <geometry>
        <mesh
          filename="${mesh_directory}/pan.stl"
          scale="0.001 0.001 0.001"/>
      </geometry>
    </collision>
    <inertial>
      <origin
        rpy="0 0 0"
        xyz="-0.000076 -0.000045 0.032138"/>
      <mass value="0.803139"/>
      <inertia
        ixx="0.0019840000"
        iyy="0.00177500000"
        izz="0.00121100000"
        ixy="0.00000000003"
        ixz="0.00000057088"
        iyz="0.00000194207"/>
    </inertial>
  </link>

  <joint name="tilt" type="revolute">
    <axis xyz="0 1 0"/>
    <limit
      effort="${tilt_limit_effort}"
      lower="${tilt_limit_lower}"
      upper="${tilt_limit_upper}"
      velocity="${tilt_limit_velocity}"/>
    <origin
      rpy="0 0 0"
      xyz="0 0 0.04805"/>
    <parent
      link="$(arg robot_name)/pan_link"/>
    <child
      link="$(arg robot_name)/tilt_link"/>
  </joint>

  <link name="$(arg robot_name)/tilt_link">
    <visual>
      <origin
        rpy="0 0 0"
        xyz="0 0 0"/>
      <geometry>
        <mesh
          filename="${mesh_directory}/tilt.stl"
          scale="0.001 0.001 0.001"/>
      </geometry>
      <material name="interbotix_black"/>
    </visual>
    <collision>
      <origin
        rpy="0 0 0"
        xyz="0 0 0"/>
      <geometry>
        <mesh
          filename="${mesh_directory}/tilt.stl"
          scale="0.001 0.001 0.001"/>
      </geometry>
    </collision>
    <inertial>
      <origin
        rpy="0 0 0"
        xyz="0 0 0.039025"/>
      <mass value="0.200466"/>
      <inertia
        ixx="0.0007562000"
        iyy="0.0004832000"
        izz="0.0006127000"
        ixy="0"
        ixz="0"
        iyz="0"/>
    </inertial>
  </link>

  <joint name="surface" type="fixed">
    <axis xyz="1 0 0"/>
    <origin
      rpy="0 0 0"
      xyz="0 0 0.045"/>
    <parent
      link="$(arg robot_name)/tilt_link"/>
    <child
      link="$(arg robot_name)/surface_link"/>
  </joint>

  <link name="$(arg robot_name)/surface_link">
  </link>

  <xacro:include filename="$(find interbotix_xsturret_descriptions)/urdf/control.urdf.xacro"/>
  <xacro:include filename="$(find interbotix_xsturret_descriptions)/urdf/gazebo_configs.urdf.xacro"/>

  <xacro:if value="${hardware_type == 'gz_classic'}">
    <xacro:gazebo_configs/>
  </xacro:if>

  <xacro:if value="${urdf_loc != ''}">
    <xacro:include filename="${urdf_loc}"/>
  </xacro:if>

</robot>
