<?xml version="1.0"?>
<robot name="wxxmd" xmlns:xacro="http://ros.org/wiki/xacro">

  <xacro:arg name="robot_name" default = "wxxmd"/>
  <xacro:arg name="base_link_frame" default="base_link"/>
  <xacro:arg name="use_world_frame" default="false"/>
  <xacro:arg name="external_urdf_loc" default=""/>
  <xacro:arg name="load_gazebo_configs" default="false"/>

  <xacro:property name="urdf_loc" value="$(arg external_urdf_loc)"/>

  <material name="interbotix_black">
    <texture filename="package://interbotix_xsturret_descriptions/meshes/interbotix_black.png"/>
  </material>

  <xacro:if value="$(arg load_gazebo_configs)">
    <xacro:include filename="$(find interbotix_xsturret_gazebo)/config/interbotix_texture.gazebo"/>
  </xacro:if>

  <xacro:if value="$(arg use_world_frame)">
    <link name="world"/>
    <joint name="fixed" type="fixed">
      <parent link="world"/>
      <child link="$(arg robot_name)/$(arg base_link_frame)"/>
    </joint>
  </xacro:if>

  <link name="$(arg robot_name)/$(arg base_link_frame)">
    <visual>
      <origin rpy="0 0 ${pi/2}" xyz="0 0 0"/>
      <geometry>
        <mesh filename="package://interbotix_xsturret_descriptions/meshes/wxxmd_meshes/wxxmd_base.stl" scale="0.001 0.001 0.001"/>
      </geometry>
      <material name="interbotix_black"/>
    </visual>
    <collision>
      <origin rpy="0 0 ${pi/2}" xyz="0 0 0"/>
      <geometry>
        <mesh filename="package://interbotix_xsturret_descriptions/meshes/wxxmd_meshes/wxxmd_base.stl" scale="0.001 0.001 0.001"/>
      </geometry>
    </collision>
    <inertial>
      <origin rpy="0 0 0" xyz="-0.032881 0.000457 0.028082"/>
      <mass value="0.720563" />
      <inertia ixx="0.0016300000" iyy="0.0041380000" izz="0.0039250000" ixy="0.0000286700" ixz="0.0004160000" iyz="-0.0000057244" />
    </inertial>
  </link>

  <joint name="pan" type="revolute">
    <axis xyz="0 0 1"/>
    <limit effort="3" lower="-3.14" upper="3.14" velocity="${pi}"/>
    <origin rpy="0 0 0" xyz="0 0 0.072"/>
    <parent link="$(arg robot_name)/$(arg base_link_frame)"/>
    <child link="$(arg robot_name)/pan_link"/>
  </joint>

  <transmission name="trans_pan">
    <type>transmission_interface/SimpleTransmission</type>
    <joint name="pan">
      <hardwareInterface>hardware_interface/EffortJointInterface</hardwareInterface>
    </joint>
    <actuator name="pan_motor">
      <mechanicalReduction>1</mechanicalReduction>
    </actuator>
  </transmission>

  <link name="$(arg robot_name)/pan_link">
    <visual>
      <origin rpy="0 0 ${pi/2}" xyz="0 0 -0.003"/>
      <geometry>
        <mesh filename="package://interbotix_xsturret_descriptions/meshes/wxxmd_meshes/wxxmd_pan.stl" scale="0.001 0.001 0.001"/>
      </geometry>
      <material name="interbotix_black"/>
    </visual>
    <collision>
      <origin rpy="0 0 ${pi/2}" xyz="0 0 -0.003"/>
      <geometry>
        <mesh filename="package://interbotix_xsturret_descriptions/meshes/wxxmd_meshes/wxxmd_pan.stl" scale="0.001 0.001 0.001"/>
      </geometry>
    </collision>
    <inertial>
      <origin rpy="0 0 0" xyz="0.000132 0.000006 0.034135"/>
      <mass value="0.333788" />
      <inertia ixx="0.0007839000" iyy="0.00060310000" izz="0.00035340000" ixy="0" ixz="-0.00000086133" iyz="-0.00000005454" />
    </inertial>
  </link>

  <joint name="tilt" type="revolute">
    <axis xyz="0 1 0"/>
    <limit effort="3" lower="${radians(-68)}" upper="${radians(68)}" velocity="${pi}"/>
    <origin rpy="0 0 0" xyz="0 0 0.03865"/>
    <parent link="$(arg robot_name)/pan_link"/>
    <child link="$(arg robot_name)/tilt_link"/>
  </joint>

  <link name="$(arg robot_name)/tilt_link">
    <visual>
      <origin rpy="0 0 0" xyz="0 0 0"/>
      <geometry>
        <mesh filename="package://interbotix_xsturret_descriptions/meshes/wxxmd_meshes/wxxmd_tilt.stl" scale="0.001 0.001 0.001"/>
      </geometry>
      <material name="interbotix_black"/>
    </visual>
    <collision>
      <origin rpy="0 0 0" xyz="0 0 0"/>
      <geometry>
        <mesh filename="package://interbotix_xsturret_descriptions/meshes/wxxmd_meshes/wxxmd_tilt.stl" scale="0.001 0.001 0.001"/>
      </geometry>
    </collision>
    <inertial>
      <origin rpy="0 0 0" xyz="0.000214 0.000087 0.030607"/>
      <mass value="0.152735" />
      <inertia ixx="0.0004951000" iyy="0.0002389000" izz="0.0004394000" ixy="-0.0000000032" ixz="-0.0000010472" iyz="-0.0000004225" />
    </inertial>
  </link>

  <transmission name="trans_tilt">
    <type>transmission_interface/SimpleTransmission</type>
    <joint name="tilt">
      <hardwareInterface>hardware_interface/EffortJointInterface</hardwareInterface>
    </joint>
    <actuator name="tilt_motor">
      <mechanicalReduction>1</mechanicalReduction>
    </actuator>
  </transmission>

  <joint name="surface" type="fixed">
    <axis xyz="1 0 0"/>
    <origin rpy="0 0 0" xyz="0 0 0.036"/>
    <parent link="$(arg robot_name)/tilt_link"/>
    <child link="$(arg robot_name)/surface_link"/>
  </joint>

  <link name="$(arg robot_name)/surface_link">
  </link>

  <xacro:if value="${urdf_loc != ''}">
    <xacro:include filename="${urdf_loc}"/>
  </xacro:if>

</robot>
